Workbook
Name ID: 'BLANKO ISIAN'!$C$13

Sheet Data
A3: ID | B3: Nama | C3: NIP | D3: PangkatGolongan | E3: Jabatan
A4: 1 | B4: Fattahurridlo Al Ghany, S.H.I., M.S.I. | C4: 198505092009041006 | D4: Pembina / IV/a | E4: Ketua
A5: 2 | B5: Nahdiyanti, S.H.I., M.H. | C5: 198410092007042001 | D5: Pembina / IV/a | E5: Wakil Ketua
A6: 3 | B6: Daru Halleila, S.H. | C6: 198604122017122001 | D6: Penata Muda TK I / III/b
A7: 4 | B7: Zahidah Alvi Qonita, S.H.I. | C7: 199312052017122001 | D7: Penata Muda TK I / III/b | E7: Hakim
A8: 5 | B8: Indra Yanita Yuliana, S.E., M.Si. | C8: 198301042006042003 | D8: Penata TK I / III/d | E8: Sekretaris
A9: 6 | B9: H. Muhammad Hamdi, S.H., M.Hum. | C9: 197503141996031002 | D9: Pembina / IV/a | E9: Panitera
A10: 7 | B10: Faridah Fitriyani, S.H.I. | C10: 198108022009122000 | D10: Penata TK I / III/d | E10: Panitera Muda Hukum
A11: 8 | B11: Nuzula Yustisia, S.H.I. | C11: 198506052009042006 | D11: Penata TK I / III/d | E11: Panitera Muda Permohonan
A12: 9 | B12: Zulfah, S.H.I. | C12: 198410212003122002 | D12: Penata / III/c | E12: Panitera Muda Hukum
A13: 10 | B13: Muhammad Zaim Noor, S.H. | C13: 198802022008051001 | D13: Penata Muda TK I / III/b | E13: Kasubag PTIP
A14: 11 | B14: Iqbal Khairillah, S.H. | C14: 198009202002121004 | D14: Penata TK I / III/d | E14: Kasubbag Kepegawaian dan Ortala
A15: 12 | B15: Muhardiansyah, S.Kom. | C15: 199107132020121003 | D15: Penata Muda / III/a | E15: Pranata Komputer
A16: 13 | B16: Muhammad Ilham, S.H., M.Kn. | C16: 199702012022031004 | D16: Penata Muda TK I / III/b | E16: Analis Perkara Peradilan
A17: 14 | B17: Raini Maulidina, S.H. | C17: 199408302020122007 | D17: Penata Muda TK I / III/b | E17: Analis Perkara Peradilan
A18: 15 | B18: Nurul Fitriani, A.Md.Kom | C18: 199304112019032020 | D18: Pengatur Tingkat I / II/d | E18: Jurusita Pengganti / Bendahara Pengeluaran
... A27: 24 | B27: Novayanti, S.H. | C27: - | D27: - | E27: PPNPN / Operator

Sheet master-pegawai
A1: No | B1: NIP | C1: Nama & Gelar | D1: Jabatan | E1: Unit Kerja | F1: TMT Jabatan | G1: Gol | H1: Jenis Pegawai | I1: jenis_jabatan
A2: 1 | B2: 198505092009041006 | C2: FATTAHURRIDLO AL GHANY, S.H.I., M.S.I. | D2: Ketua | E2: Pengadilan Agama Penajam | F2: 13 Mei 2024 | G2: IV/a | H2: Hakim | I2: pimpinan
A3: 2 | B3: 198410092007042001 | C3: NAHDIYANTI, S.H.I., M.H. | D3: Wakil Ketua | E3: Pengadilan Agama Penajam | F3: 28 Nov 2022 | G3: IV/a | H3: Hakim | I3: pimpinan
A4: 3 | B4: 199702232022032013 | C4: NUR RIZKA FANI, S.H. | D4: Hakim Pratama | E4: Pengadilan Agama Penajam | F4: 11 Juni 2025 | G4: III/a | H4: Hakim | I4: pimpinan
A5: 4 | B5: 199704162022032013 | C5: VIDYA NURCHALIZA, S.H. | D5: Hakim Pratama | E5: Pengadilan Agama Penajam | F5: 11 Juni 2025 | G5: III/a | H5: Hakim | I5: pimpinan
A6: 5 | B6: 197503141996031002 | C6: MUHAMMAD HAMDI, S.H., M.Hum. | D6: Panitera | E6: Kepaniteraan | F6: 11 Juni 2024 | G6: IV/a | H6: PNS | I6: pimpinan
A7: 6 | B7: 198301042006042003 | C7: INDRA YANITA YULIANA, S.E., M.Si. | D7: Sekretaris | E7: Kesekretariatan | F7: 07 Agt 2019 | G7: IV/a | H7: PNS | I7: pimpinan
A8: 7 | B8: 198506052009042006 | C8: NUZULA YUSTISIA, S.H.I. | D8: Panmud Permohonan | E8: Kepaniteraan | F8: 21 Juli 2025 | G8: III/d | H8: PNS | I8: Struktural
A9: 8 | B9: 198108022009122002 | C9: FARIDAH FITRIYANI, S.H.I. | D9: Panmud Gugatan | E9: Kepaniteraan | F9: 10 Okt 2024 | G9: III/d | H9: PNS | I9: Struktural
A10: 9 | B10: 198411192011011012 | C10: AWALUDDIN NUR, S.H.I. | D10: Kasubbag PTIP | E10: Kesekretariatan | F10: 28 Agt 2025 | G10: III/d | H10: PNS | I10: Struktural
A11: 10 | B11: 198802022008051001 | C11: MUHAMMAD ZAIM NOOR, S.H. | D11: Kasubbag Umum & Keu | E11: Kesekretariatan | F11: 28 Agt 2025 | G11: III/c | H11: PNS | I11: Struktural
A12: 11 | B12: 199408302020122007 | C12: RAINI MAULIDINA, S.H. | D12: Panitera Pengganti | E12: Kepaniteraan | F12: 17 Juni 2025 | G12: III/b | H12: PNS | I12: Fungsional
A13: 12 | B13: 199705312020121004 | C13: MUHAMMAD MIFTAHUDIN, S.H. | D13: Panitera Pengganti | E13: Kepaniteraan | F13: 17 Juni 2025 | G13: III/b | H13: PNS | I13: Fungsional
... A30: 29 | B30: 199304112019032020 | C30: NURUL FITRIANI, A.Md.Kom. | D30: Juru Sita Pengganti | E30: Kepaniteraan | F30: 09 Okt 2023 | G30: II/d | H30: PNS | I30: Fungsional

Sheet SPPD LMBAR 1
A1: MAHKAMAH AGUNG REPUBLIK INDONESIA
A2: DIREKTORAT JENDERAL BADAN PERADILAN AGAMA
A3: PENGADILAN TINGGI AGAMA SAMARINDA
A4: PENGADILAN AGAMA PENAJAM
A5: Jl. Provinsi KM. 09, Kelurahan Nipah-Nipah, Kecamatan Penajam
A6: Kabupaten Penajam Paser Utara, Provinsi Kalimantan Timur
A7: Telp. 0542-8541119, papnj@pa-penajam.go.id, www.pa-penajam.go.id
H9: Lembar ke | I9: : | J9: ='BLANKO ISIAN'!$C$5 -> 1
H10: Kode No | I10: : | K10: ='BLANKO ISIAN'!D7 -> /SPD/2026
H11: Nomor | I11: : | J11: ='BLANKO ISIAN'!C9 -> 25/KPA.W17-A8/KP7.1/I/2026
A13: SURAT PERJALANAN DINAS
A15: 1. | B15: Pejabat Pembuat Komitmen Pengadilan Agama Penajam | E15: ='BLANKO ISIAN'!$C$11 -> Muhammad Zaim Noor, S.H.
E16: ='BLANKO ISIAN'!$C$12 -> NIP. 19880202 200805 1 001
A17: 2. | B17: Nama / NIP Pegawai yang melaksanakan perjalanan dinas | E17: ='BLANKO ISIAN'!$C$14 -> Muhammad Zaim Noor, S.H.
E18: ='BLANKO ISIAN'!C15 -> NIP. 200106132024052000
A19: 3. | B19: a. | C19: Pangkat dan golongan ruang gaji menurut PP No.6 Tahun 1997 | E19: a. | F19: ='BLANKO ISIAN'!C17 -> Penata Muda / III/a
B20: b. | C20: Jabatan/Instansi | E20: b. | F20: ='BLANKO ISIAN'!C19 -> Analis Perkara Peradilan
B21: c. | C21: Tingkat menurut peraturan perjalanan dinas | E21: c. | F21: ='BLANKO ISIAN'!$C$21 -> Tingkat C
A22: 4. | B22: Maksud perjalanan dinas | E22: Berangkat ke | H22: ='BLANKO ISIAN'!$C$23 -> Kecamatan Sepaku
E23: dalam rangka | H23: ='BLANKO ISIAN'!$C$26 -> Verifikasi sidang di luar gedung Kecamatan Sepaku
A24: 5. | B24: Alat angkut yang dipergunakan | E24: ='BLANKO ISIAN'!$C$28 -> Angkutan Darat dan Laut
A25: 6. | B25: a. | C25: Tempat berangkat | E25: a. | F25: ='BLANKO ISIAN'!$C$30 -> Penajam
B26: b. | C26: Tempat tujuan | E26: b. | F26: ='BLANKO ISIAN'!$C$32 -> Sepaku
A27: 7. | B27: a. | C27: Lamanya perjalanan dinas | E27: a. | F27: ='BLANKO ISIAN'!$C$34 -> 2 | G27: Hari
B28: b. | C28: Tanggal berangkat | E28: b. | F28: ='BLANKO ISIAN'!$C$36 -> 8 Januari 2026
B29: c. | C29: Tanggal harus kembali/tiba ditempat baru*) | E29: c. | F29: ='BLANKO ISIAN'!$C$38 -> 9 Januari 2026
A30: 8. | B30: Nama pengikut : | E30: Tanggal Lahir | J30: Keterangan
B31: 1. | C31: ='BLANKO ISIAN'!$B$42 -> 0 | E31: ='BLANKO ISIAN'!$C$42 -> 0 | J31: ='BLANKO ISIAN'!$D$42 -> 0
B32: 2. | C32: ='BLANKO ISIAN'!$B$43 -> 0 | E32: ='BLANKO ISIAN'!$C$43 -> 0 | J32: ='BLANKO ISIAN'!$D$43 -> 0
B33: 3. | C33: ='BLANKO ISIAN'!$B$44 -> 0 | E33: ='BLANKO ISIAN'!$C$44 -> 0 | J33: ='BLANKO ISIAN'!$D$44 -> 0
B34: 4. | C34: ='BLANKO ISIAN'!$B$45 -> 0 | E34: ='BLANKO ISIAN'!$C$45 -> 0 | J34: ='BLANKO ISIAN'!$D$45 -> 0
A35: 9. | B35: Pembebanan anggaran :
B36: a. | C36: Instansi | E36: a. | F36: ='BLANKO ISIAN'!$C$49 -> Pengadilan Agama Penajam
B37: b. | C37: Akun | E37: b. | F37: ='BLANKO ISIAN'!$C$50 -> 524113
A38: 10. | B38: Keterangan lain-lain :
G40: Dikeluarkan di | I40: : | J40: ='BLANKO ISIAN'!$C$52 -> Penajam
G41: Tanggal | I41: : | J41: ='BLANKO ISIAN'!$C$53 -> 7 Januari 2026
G43: Pejabat Pembuat Komitmen
G44: Pengadilan Agama Penajam
G48: Muhammad Zaim Noor, S.H.
...

Sheet SPPD LEMBAR 2
F1: I | G1: Berangkat dari (tempat kedudukan) | H1: : | I1: ='BLANKO ISIAN'!$C$30 -> Penajam
G2: Pada tanggal | H2: : | I2: ='BLANKO ISIAN'!$C$36 -> 8 Januari 2026
G3: ke | H3: : | I3: ='BLANKO ISIAN'!$C$32 -> Sepaku
G5: Ketua | P5: Sekretaris | V5: Ketua
G6: ='BLANKO ISIAN'!$C$56 -> Pengadilan Agama Penajam | P6: ='BLANKO ISIAN'!$C$56 -> Pengadilan Agama Penajam | V6: Pengadilan Agama Penajam
G10: FATTAHURRIDLO AL GHANY, S.H.I., M.S.I | H10: H. ACHMAD FAUSI, S.H.I. M.H. | I10: H. ACHMAD FAUSI, S.H.I. M.H. | J10: H. ACHMAD FAUSI, S.H.I. M.H. | K10: H. ACHMAD FAUSI, S.H.I. M.H. | V10: H. ACHMAD FAUSI, S.H.I. M.H.
G11: NIP. 198505092009041006 | H11: NIP.198108032007041001 | I11: NIP.198108032007041001 | J11: NIP.198108032007041001 | K11: NIP.198108032007041001 | P11: INDRA YANITA YULIANA, S.E., M.Si. NIP.198301042006042003 | V11: NIP.198108032007041001
P12: NIP. 198301042006042003
A15: II | B15: Tiba di | C15: : | G15: Berangkat dari | H15: :
B16: pada tanggal | C16: : | G16: Ke | H16: :
G17: Pada tanggal | H17: :
P18: ='[1]BLANKO ISIAN'!L70 -> 0
P19: ='[1]BLANKO ISIAN'!$C$55 -> Pengadilan Agama Penajam
P23: ='[1]BLANKO ISIAN'!L71 -> 0
P24: ='[1]BLANKO ISIAN'!L72 -> 0
C25: NIP. | H25: NIP.
A28: III | B28: Tiba di | C28: : | G28: Berangkat dari | H28: :
B29: pada tanggal | C29: : | G29: Ke | H29: :
G30: Pada tanggal | H30: :
C36: NIP. | H36: NIP.
A39: IV | B39: Tiba di | C39: : | G39: Berangkat dari | H39: :
B40: pada tanggal | C40: : | G40: Ke | H40: :
G41: Pada tanggal | H41: :
C47: NIP. | H47: NIP.
G49: Telah diperiksa dengan keterangan bahwa perjalanan -
A50: V | B50: Tiba di | C50: : | D50: =I1 -> Penajam | G50: tersebut diatas benar dilakukan atas perintahnya dan
B51: (tempat kedudukan) | G51: semata-mata untuk kepentinganjabatandalam waktu yang
B52: Pada Tanggal | C52: : | G52: sesingkat-singkatnya.
B53: Pejabat yang memberi perintah: | G53: =$B$53 -> Pejabat yang memberi perintah:
B55: PEJABAT PEMBUAT KOMITMEN, | G55: =$B$55 -> PEJABAT PEMBUAT KOMITMEN,
B56: ='BLANKO ISIAN'!$C$56 -> Pengadilan Agama Penajam | G56: =$B$56 -> Pengadilan Agama Penajam
B61: ='BLANKO ISIAN'!$C$62 -> Muhammad Zaim Noor, S.H. | G61: ='BLANKO ISIAN'!$C$62 -> Muhammad Zaim Noor, S.H.
B62: ='BLANKO ISIAN'!$C$63 -> NIP. 19880202 200805 1 001 | G62: ='BLANKO ISIAN'!$C$63 -> NIP. 19880202 200805 1 001
A63: VI. | B63: Catatan lain-lain :
A65: VII. | B65: PERHATIAN
B66: Pejabat yang berwenang menerbitkan SPPD, pegawai yang melakukan perjalanan dinas, para pejabat yang mengesahkan tanggal berangkat/tiba serta bendaharawan bertanggung jawab berdasarkan peraturan-peraturan Keuangan Negara apabila negara menderita kerugian akibat kesalahan,kelalaian dan kealpaannya.

Sheet BLANKO ISIAN
A1: BLANKO ISIAN SPPD
A3: NO | B3: PERIHAL | C3: ISIAN
A5: 1 | B5: Lembar SPPD ke | C5: 1
G6: ID | H6: Nama | I6: NIP | J6: PangkatGolongan | K6: Jabatan
A7: 2 | B7: Kode SPPD No | D7: /SPD/2026 | G7: 1 | H7: Fattahurridlo Al Ghany, S.H.I., M.S.I. | I7: NIP. 198505092009041006 | J7: Pembina / IV/a | K7: Ketua / Pengadilan Agama Penajam
G8: 2 | H8: Nahdiyanti, S.H.I., M.H. | I8: NIP. 198410092007042001 | J8: Pembina / IV/a | K8: Wakil Ketua / Pengadilan Agama Penajam
A9: 3 | B9: Nomor | C9: 25/KPA.W17-A8/KP7.1/I/2026 | G9: 3 | H9: Daru Halleila, S.H. | I9: NIP. 198604122017122001 | J9: Penata Muda TK I / III/b | K9: Hakim / Pengadilan Agama Penajam
G10: 4 | H10: Zahidah Alvi Qonita, S.H.I. | I10: NIP. 199312052017122001 | J10: Penata Muda TK I / III/b | K10: Hakim / Pengadilan Agama Penajam
A11: 4 | B11: Nama pejabat berwenang yang memberi perintah | C11: Muhammad Zaim Noor, S.H. | G11: 5 | H11: Indra Yanita Yuliana, S.E., M.Si. | I11: NIP. 198301042006042003 | J11: Penata TK I / III/d | K11: Sekretaris / Pengadilan Agama Penajam
B12: (nip) | C12: NIP. 19880202 200805 1 001 | G12: 6 | H12: H. Muhammad Hamdi, S.H., M.Hum | I12: NIP. 197503141996031002 | J12: Pembina / IV/a | K12: Panitera / Pengadilan Agama Penajam
B13: Nomor Urut Data | G13: 7 | H13: Faridah Fitriyani, S.H.I. | I13: NIP. 198108022009122002 | J13: Penata TK I / III/d | K13: Panitera Muda Gugatan / Pengadilan Agama Penajam
A14: 5 | B14: Nama / NIP Pegawai yang melaksanakan perjalanan dinas | C14: Muhammad Zaim Noor, S.H. | G14: 8 | H14: Nuzula Yustisia, S.H.I. | I14: NIP. 198506052009042006 | J14: Penata TK I / III/d | K14: Panitera Pengganti / Pengadilan Agama Penajam
C15: NIP. 200106132024052000 | G15: 9 | H15: Zulfah, S.H.I. | I15: NIP. 198410212003122002 | J15: Penata / III/c | K15: Panitera Muda Hukum / Pengadilan Agama Penajam
G16: 10 | H16: Muhammad Zaim Noor, S.H. | I16: NIP. 198802022008051001 | J16: Penata/ III/c | K16: Kasubag Umum dan Keuangan / Pengadilan Agama Penajam
A17: 6 | B17: Pangkat dan golongan ruang gaji menurut PP No.6 Tahun 1997 | C17: Penata Muda / III/a | G17: 11 | H17: Iqbal Khairillah, S.H. | I17: NIP. 198009202002121004 | J17: Penata TK I / III/d | K17: Kasubbag Kepegawaian dan Ortala / Pengadilan Agama Penajam
G18: 12 | H18: Muhardiansyah, S.Kom. | I18: NIP. 199107132020121003 | J18: Penata Muda / III/a | K18: Pranata Komputer / Pengadilan Agama Penajam
A19: 7 | B19: Jabatan/Instansi | C19: Analis Perkara Peradilan | G19: 13 | H19: Muhammad Ilham, S.H., M.Kn. | I19: NIP. 199702012022031004 | J19: Penata Muda TK I / III/b | K19: Analis Perkara Peradilan / Pengadilan Agama Penajam
G20: 14 | H20: Raini Maulidina, S.H. | I20: NIP. 199408302020122007 | J20: Penata Muda TK I / III/b | K20: Analis Perkara Peradilan / Pengadilan Agama Penajam
A21: 8 | B21: Tingkat menurut peraturan perjalanan dinas | C21: Tingkat C | G21: 15 | H21: Nurul Fitriani, A.Md.Kom | I21: NIP. 199304112019032020 | J21: Pengatur Tingkat I / II/d | K21: Jurusita Pengganti / Bendahara Pengeluaran
G22: 16 | H22: Yulinda, A.Md.Kom. | I22: NIP. 199211132020122011 | J22: Pengatur / II/c | K22: Pengelola Perkara / Pengadilan Agama Penajam
A23: 9 | B23: Berangkat ke | C23: Kecamatan Sepaku | G23: 17 | H23: Irwan Syah Setiawan, A.md | I23: NIP. 199010082022031004 | J23: Pengatur / II/c | K23: Pengelola Perkara / Pengadilan Agama Penajam
G24: 18 | H24: Amin Nur | I24: - | J24: - | K24: PPNPN / Supir
G25: 19 | H25: Adi Irawan | I25: - | J25: - | K25: PPNPN / Supir
A26: 10 | B26: Dalam rangka | C26: Verifikasi sidang di luar gedung Kecamatan Sepaku | G26: 20 | H26: Najwa Hijriana | I26: - | J26: - | K26: PPNPN / Operator
G27: 21 | H27: Damai Azizu, S.Kom. | I27: - | J27: - | K27: PPNPN / Supir
A28: 11 | B28: Alat angkut yang dipergunakan | C28: Angkutan Darat dan Laut | G28: 22 | H28: Qurrotu Aini, S.H. | I28: NIP. 200106132024052000 | J28: Penata Muda / III/a | K28: Analis Perkara Peradilan
G29: 23 | H29: Ashar, S.H. | I29: NIP. 199406072025211039 | J29: IX | K29: Penata layanan Operasional / Pengadilan Agama Penajam
A30: 12 | B30: Tempat berangkat | C30: Penajam | G30: 24 | H30: Novayanti, S.H. | I30: - | J30: - | K30: PPNPN / Operator
G31: 25 | H31: Nur Muflihah Putri Wijanarko, S.T. | I31: NIP. 199710252025062012 | J31: Penata Muda / III/a | K31: Teknisi Sarana dan Prasarana / Pengadilan Agama Penajam
A32: 13 | B32: Tempat tujuan | C32: Sepaku
A34: 14 | B34: Lamanya perjalanan dinas | C34: 2
A36: 15 | B36: Tanggal keberangkatan | C36: 8 Januari 2026
A38: 16 | B38: Tanggal harus kembali | C38: 9 Januari 2026
A40: 17 | B40: Nama Pengikut | C40: tanggal lahir | D40: keterangan
A42: *
A43: *
A44: *
A45: *
A46: *
A48: 18 | B48: Pembebanan anggaran pada
...
